Workbook

Sheet Management Dashboard
A1: VENDOR PAYABLE MANAGEMENT DASHBOARD
A2: Single master workbook — all vendor ledgers are contained here
A4: Active Vendors | B4: =COUNTA('Vendor Master'!A6:A15) | D4: Total Debit | E4: =SUM(Transactions!F:F) | G4: Total Credit | H4: =SUM(Transactions!G:G) | J4: Net Payable | K4: =SUM('Ledger Index'!H6:H15)
A7: Vendor Payable Summary
A8: Vendor ID | B8: Vendor Name | C8: Category | D8: Opening | E8: Debit | F8: Credit | G8: Closing
A9: ='Ledger Index'!A6 | B9: ='Ledger Index'!B6 | C9: ='Ledger Index'!C6 | D9: ='Ledger Index'!E6 | E9: ='Ledger Index'!F6 | F9: ='Ledger Index'!G6 | G9: ='Ledger Index'!H6
A10: ='Ledger Index'!A7 | B10: ='Ledger Index'!B7 | C10: ='Ledger Index'!C7 | D10: ='Ledger Index'!E7 | E10: ='Ledger Index'!F7 | F10: ='Ledger Index'!G7 | G10: ='Ledger Index'!H7
A11: ='Ledger Index'!A8 | B11: ='Ledger Index'!B8 | C11: ='Ledger Index'!C8 | D11: ='Ledger Index'!E8 | E11: ='Ledger Index'!F8 | F11: ='Ledger Index'!G8 | G11: ='Ledger Index'!H8
A12: ='Ledger Index'!A9 | B12: ='Ledger Index'!B9 | C12: ='Ledger Index'!C9 | D12: ='Ledger Index'!E9 | E12: ='Ledger Index'!F9 | F12: ='Ledger Index'!G9 | G12: ='Ledger Index'!H9
A13: ='Ledger Index'!A10 | B13: ='Ledger Index'!B10 | C13: ='Ledger Index'!C10 | D13: ='Ledger Index'!E10 | E13: ='Ledger Index'!F10 | F13: ='Ledger Index'!G10 | G13: ='Ledger Index'!H10
A14: ='Ledger Index'!A11 | B14: ='Ledger Index'!B11 | C14: ='Ledger Index'!C11 | D14: ='Ledger Index'!E11 | E14: ='Ledger Index'!F11 | F14: ='Ledger Index'!G11 | G14: ='Ledger Index'!H11
A15: ='Ledger Index'!A12 | B15: ='Ledger Index'!B12 | C15: ='Ledger Index'!C12 | D15: ='Ledger Index'!E12 | E15: ='Ledger Index'!F12 | F15: ='Ledger Index'!G12 | G15: ='Ledger Index'!H12
A16: ='Ledger Index'!A13 | B16: ='Ledger Index'!B13 | C16: ='Ledger Index'!C13 | D16: ='Ledger Index'!E13 | E16: ='Ledger Index'!F13 | F16: ='Ledger Index'!G13 | G16: ='Ledger Index'!H13
A17: ='Ledger Index'!A14 | B17: ='Ledger Index'!B14 | C17: ='Ledger Index'!C14 | D17: ='Ledger Index'!E14 | E17: ='Ledger Index'!F14 | F17: ='Ledger Index'!G14 | G17: ='Ledger Index'!H14
A18: ='Ledger Index'!A15 | B18: ='Ledger Index'!B15 | C18: ='Ledger Index'!C15 | D18: ='Ledger Index'!E15 | E18: ='Ledger Index'!F15 | F18: ='Ledger Index'!G15 | G18: ='Ledger Index'!H15

Sheet Ledger Index
A1: VENDOR LEDGER INDEX
A2: Click any vendor name to jump to that vendor's ledger sheet
A3: Navigation: tap/click the blue Vendor Name or OPEN LEDGER → button.
A5: Vendor ID | B5: Vendor Name | C5: Category | D5: Status | E5: Opening Balance | F5: Debit | G5: Credit | H5: Closing Balance | I5: Open Ledger
A6: V001 | B6: Alpha Yarn Suppliers | C6: Yarn | D6: Active | E6: =XLOOKUP(A6,'Vendor Master'!A6:A15,'Vendor Master'!G6:G15,0) | F6: =SUMIFS(Transactions!F:F,Transactions!C:C,A6) | G6: =SUMIFS(Transactions!G:G,Transactions!C:C,A6) | H6: =E6+F6-G6 | I6: OPEN LEDGER →
A7: V002 | B7: Pak Textile Traders | C7: Textile | D7: Active | E7: =XLOOKUP(A7,'Vendor Master'!A6:A15,'Vendor Master'!G6:G15,0) | F7: =SUMIFS(Transactions!F:F,Transactions!C:C,A7) | G7: =SUMIFS(Transactions!G:G,Transactions!C:C,A7) | H7: =E7+F7-G7 | I7: OPEN LEDGER →
A8: V003 | B8: Faisal Engineering Works | C8: Engineering | D8: Active | E8: =XLOOKUP(A8,'Vendor Master'!A6:A15,'Vendor Master'!G6:G15,0) | F8: =SUMIFS(Transactions!F:F,Transactions!C:C,A8) | G8: =SUMIFS(Transactions!G:G,Transactions!C:C,A8) | H8: =E8+F8-G8 | I8: OPEN LEDGER →
A9: V004 | B9: City Packing Solutions | C9: Packing | D9: Active | E9: =XLOOKUP(A9,'Vendor Master'!A6:A15,'Vendor Master'!G6:G15,0) | F9: =SUMIFS(Transactions!F:F,Transactions!C:C,A9) | G9: =SUMIFS(Transactions!G:G,Transactions!C:C,A9) | H9: =E9+F9-G9 | I9: OPEN LEDGER →
A10: V005 | B10: Prime Chemical Suppliers | C10: Chemicals | D10: Active | E10: =XLOOKUP(A10,'Vendor Master'!A6:A15,'Vendor Master'!G6:G15,0) | F10: =SUMIFS(Transactions!F:F,Transactions!C:C,A10) | G10: =SUMIFS(Transactions!G:G,Transactions!C:C,A10) | H10: =E10+F10-G10 | I10: OPEN LEDGER →
A11: V006 | B11: Metro Electricals | C11: Electrical | D11: Active | E11: =XLOOKUP(A11,'Vendor Master'!A6:A15,'Vendor Master'!G6:G15,0) | F11: =SUMIFS(Transactions!F:F,Transactions!C:C,A11) | G11: =SUMIFS(Transactions!G:G,Transactions!C:C,A11) | H11: =E11+F11-G11 | I11: OPEN LEDGER →
A12: V007 | B12: United Spare Parts | C12: Spare Parts | D12: Active | E12: =XLOOKUP(A12,'Vendor Master'!A6:A15,'Vendor Master'!G6:G15,0) | F12: =SUMIFS(Transactions!F:F,Transactions!C:C,A12) | G12: =SUMIFS(Transactions!G:G,Transactions!C:C,A12) | H12: =E12+F12-G12 | I12: OPEN LEDGER →
A13: V008 | B13: National Transport Services | C13: Transport | D13: Active | E13: =XLOOKUP(A13,'Vendor Master'!A6:A15,'Vendor Master'!G6:G15,0) | F13: =SUMIFS(Transactions!F:F,Transactions!C:C,A13) | G13: =SUMIFS(Transactions!G:G,Transactions!C:C,A13) | H13: =E13+F13-G13 | I13: OPEN LEDGER →
A14: V009 | B14: Quality Lubricants | C14: Lubricants | D14: Active | E14: =XLOOKUP(A14,'Vendor Master'!A6:A15,'Vendor Master'!G6:G15,0) | F14: =SUMIFS(Transactions!F:F,Transactions!C:C,A14) | G14: =SUMIFS(Transactions!G:G,Transactions!C:C,A14) | H14: =E14+F14-G14 | I14: OPEN LEDGER →
A15: V010 | B15: Industrial Safety House | C15: Safety | D15: Active | E15: =XLOOKUP(A15,'Vendor Master'!A6:A15,'Vendor Master'!G6:G15,0) | F15: =SUMIFS(Transactions!F:F,Transactions!C:C,A15) | G15: =SUMIFS(Transactions!G:G,Transactions!C:C,A15) | H15: =E15+F15-G15 | I15: OPEN LEDGER →

Sheet Vendor Master
A1: VENDOR MASTER
A2: Central vendor reference data
A5: Vendor ID | B5: Vendor Name | C5: Category | D5: Contact Person | E5: Payment Terms | F5: Credit Limit | G5: Opening Balance | H5: Status
A6: V001 | B6: Alpha Yarn Suppliers | C6: Yarn | D6: Alpha Yarn Suppliers Accounts | E6: 30 Days | F6: 500000 | G6: 100000 | H6: Active
A7: V002 | B7: Pak Textile Traders | C7: Textile | D7: Pak Textile Traders Accounts | E7: 30 Days | F7: 500000 | G7: 100000 | H7: Active
A8: V003 | B8: Faisal Engineering Works | C8: Engineering | D8: Faisal Engineering Works Accounts | E8: 30 Days | F8: 500000 | G8: 100000 | H8: Active
A9: V004 | B9: City Packing Solutions | C9: Packing | D9: City Packing Solutions Accounts | E9: 30 Days | F9: 500000 | G9: 100000 | H9: Active
A10: V005 | B10: Prime Chemical Suppliers | C10: Chemicals | D10: Prime Chemical Suppliers Accounts | E10: 30 Days | F10: 500000 | G10: 100000 | H10: Active
A11: V006 | B11: Metro Electricals | C11: Electrical | D11: Metro Electricals Accounts | E11: 30 Days | F11: 500000 | G11: 100000 | H11: Active
A12: V007 | B12: United Spare Parts | C12: Spare Parts | D12: United Spare Parts Accounts | E12: 30 Days | F12: 500000 | G12: 100000 | H12: Active
A13: V008 | B13: National Transport Services | C13: Transport | D13: National Transport Services Accounts | E13: 30 Days | F13: 500000 | G13: 100000 | H13: Active
A14: V009 | B14: Quality Lubricants | C14: Lubricants | D14: Quality Lubricants Accounts | E14: 30 Days | F14: 500000 | G14: 100000 | H14: Active
A15: V010 | B15: Industrial Safety House | C15: Safety | D15: Industrial Safety House Accounts | E15: 30 Days | F15: 500000 | G15: 100000 | H15: Active

Sheet Transactions
A1: VENDOR TRANSACTIONS
A2: Central entry register — ledgers update from this sheet
A5: Date | B5: Voucher No. | C5: Vendor ID | D5: Vendor Name | E5: Description | F5: Debit | G5: Credit | H5: Reference | I5: Entered By | J5: Month
A6: 46266 | B6: JV-1006 | C6: V001 | D6: =IFERROR(XLOOKUP(C6,'Vendor Master'!$A$6:$A$15,'Vendor Master'!$B$6:$B$15,""),"") | E6: Purchase Invoice | F6: 0 | G6: 35000 | H6: REF-0006 | I6: Finance | J6: =IF(A6="","",TEXT(A6,"mmm-yyyy"))
A7: 46267 | B7: JV-1007 | C7: V002 | D7: =IFERROR(XLOOKUP(C7,'Vendor Master'!$A$6:$A$15,'Vendor Master'!$B$6:$B$15,""),"") | E7: Yarn Purchase | F7: 57250 | G7: 0 | H7: REF-0007 | I7: Finance | J7: =IF(A7="","",TEXT(A7,"mmm-yyyy"))
A8: 46268 | B8: JV-1008 | C8: V003 | D8: =IFERROR(XLOOKUP(C8,'Vendor Master'!$A$6:$A$15,'Vendor Master'!$B$6:$B$15,""),"") | E8: Spare Parts Purchase | F8: 64500 | G8: 0 | H8: REF-0008 | I8: Finance | J8: =IF(A8="","",TEXT(A8,"mmm-yyyy"))
A9: 46269 | B9: JV-1009 | C9: V004 | D9: =IFERROR(XLOOKUP(C9,'Vendor Master'!$A$6:$A$15,'Vendor Master'!$B$6:$B$15,""),"") | E9: Packing Material | F9: 0 | G9: 50000 | H9: REF-0009 | I9: Finance | J9: =IF(A9="","",TEXT(A9,"mmm-yyyy"))
A10: 46270 | B10: JV-1010 | C10: V005 | D10: =IFERROR(XLOOKUP(C10,'Vendor Master'!$A$6:$A$15,'Vendor Master'!$B$6:$B$15,""),"") | E10: Service Invoice | F10: 79000 | G10: 0 | H10: REF-0010 | I10: Finance | J10: =IF(A10="","",TEXT(A10,"mmm-yyyy"))
A11: 46271 | B11: JV-1011 | C11: V006 | D11: =IFERROR(XLOOKUP(C11,'Vendor Master'!$A$6:$A$15,'Vendor Master'!$B$6:$B$15,""),"") | E11: Payment to Vendor | F11: 86250 | G11: 0 | H11: REF-0011 | I11: Finance | J11: =IF(A11="","",TEXT(A11,"mmm-yyyy"))
A12: 46272 | B12: JV-1012 | C12: V007 | D12: =IFERROR(XLOOKUP(C12,'Vendor Master'!$A$6:$A$15,'Vendor Master'!$B$6:$B$15,""),"") | E12: Transport Charges | F12: 0 | G12: 65000 | H12: REF-0012 | I12: Finance | J12: =IF(A12="","",TEXT(A12,"mmm-yyyy"))
A13: 46273 | B13: JV-1013 | C13: V008 | D13: =IFERROR(XLOOKUP(C13,'Vendor Master'!$A$6:$A$15,'Vendor Master'!$B$6:$B$15,""),"") | E13: Maintenance Purchase | F13: 100750 | G13: 0 | H13: REF-0013 | I13: Finance | J13: =IF(A13="","",TEXT(A13,"mmm-yyyy"))
A14: 46274 | B14: JV-1014 | C14: V009 | D14: =IFERROR(XLOOKUP(C14,'Vendor Master'!$A$6:$A$15,'Vendor Master'!$B$6:$B$15,""),"") | E14: Purchase Invoice | F14: 108000 | G14: 0 | H14: REF-0014 | I14: Finance | J14: =IF(A14="","",TEXT(A14,"mmm-yyyy"))
A15: 46275 | B15: JV-1015 | C15: V010 | D15: =IFERROR(XLOOKUP(C15,'Vendor Master'!$A$6:$A$15,'Vendor Master'!$B$6:$B$15,""),"") | E15: Yarn Purchase | F15: 0 | G15: 80000 | H15: REF-0015 | I15: Finance | J15: =IF(A15="","",TEXT(A15,"mmm-yyyy"))
A16: 46276 | B16: JV-1016 | C16: V001 | D16: =IFERROR(XLOOKUP(C16,'Vendor Master'!$A$6:$A$15,'Vendor Master'!$B$6:$B$15,""),"") | E16: Spare Parts Purchase | F16: 122500 | G16: 0 | H16: REF-0016 | I16: Finance | J16: =IF(A16="","",TEXT(A16,"mmm-yyyy"))
A17: 46277 | B17: JV-1017 | C17: V002 | D17: =IFERROR(XLOOKUP(C17,'Vendor Master'!$A$6:$A$15,'Vendor Master'!$B$6:$B$15,""),"") | E17: Packing Material | F17: 129750 | G17: 0 | H17: REF-0017 | I17: Finance | J17: =IF(A17="","",TEXT(A17,"mmm-yyyy"))
... A25: 46270 | B25: JV-1025 | C25: V010 | D25: =IFERROR(XLOOKUP(C25,'Vendor Master'!$A$6:$A$15,'Vendor Master'!$B$6:$B$15,""),"") | E25: Packing Material | F25: 107750 | G25: 0 | H25: REF-0025 | I25: Finance | J25: =IF(A25="","",TEXT(A25,"mmm-yyyy"))
D26: =IFERROR(XLOOKUP(C26,'Vendor Master'!$A$6:$A$15,'Vendor Master'!$B$6:$B$15,""),"") | J26: =IF(A26="","",TEXT(A26,"mmm-yyyy"))
D27: =IFERROR(XLOOKUP(C27,'Vendor Master'!$A$6:$A$15,'Vendor Master'!$B$6:$B$15,""),"") | J27: =IF(A27="","",TEXT(A27,"mmm-yyyy"))
D28: =IFERROR(XLOOKUP(C28,'Vendor Master'!$A$6:$A$15,'Vendor Master'!$B$6:$B$15,""),"") | J28: =IF(A28="","",TEXT(A28,"mmm-yyyy"))
D29: =IFERROR(XLOOKUP(C29,'Vendor Master'!$A$6:$A$15,'Vendor Master'!$B$6:$B$15,""),"") | J29: =IF(A29="","",TEXT(A29,"mmm-yyyy"))
D30: =IFERROR(XLOOKUP(C30,'Vendor Master'!$A$6:$A$15,'Vendor Master'!$B$6:$B$15,""),"") | J30: =IF(A30="","",TEXT(A30,"mmm-yyyy"))
D31: =IFERROR(XLOOKUP(C31,'Vendor Master'!$A$6:$A$15,'Vendor Master'!$B$6:$B$15,""),"") | J31: =IF(A31="","",TEXT(A31,"mmm-yyyy"))
D32: =IFERROR(XLOOKUP(C32,'Vendor Master'!$A$6:$A$15,'Vendor Master'!$B$6:$B$15,""),"") | J32: =IF(A32="","",TEXT(A32,"mmm-yyyy"))
D33: =IFERROR(XLOOKUP(C33,'Vendor Master'!$A$6:$A$15,'Vendor Master'!$B$6:$B$15,""),"") | J33: =IF(A33="","",TEXT(A33,"mmm-yyyy"))
D34: =IFERROR(XLOOKUP(C34,'Vendor Master'!$A$6:$A$15,'Vendor Master'!$B$6:$B$15,""),"") | J34: =IF(A34="","",TEXT(A34,"mmm-yyyy"))
D35: =IFERROR(XLOOKUP(C35,'Vendor Master'!$A$6:$A$15,'Vendor Master'!$B$6:$B$15,""),"") | J35: =IF(A35="","",TEXT(A35,"mmm-yyyy"))
D36: =IFERROR(XLOOKUP(C36,'Vendor Master'!$A$6:$A$15,'Vendor Master'!$B$6:$B$15,""),"") | J36: =IF(A36="","",TEXT(A36,"mmm-yyyy"))
D37: =IFERROR(XLOOKUP(C37,'Vendor Master'!$A$6:$A$15,'Vendor Master'!$B$6:$B$15,""),"") | J37: =IF(A37="","",TEXT(A37,"mmm-yyyy"))
... D5000: =IFERROR(XLOOKUP(C5000,'Vendor Master'!$A$6:$A$15,'Vendor Master'!$B$6:$B$15,""),"") | J5000: =IF(A5000="","",TEXT(A5000,"mmm-yyyy"))

Sheet V001
A1: ALPHA YARN SUPPLIERS — VENDOR LEDGER
A2: Vendor ID: V001 | Category: Yarn | Linked to Transactions
A3: Vendor ID | B3: V001 | D3: ← BACK TO LEDGER INDEX
A5: Opening Balance | B5: =XLOOKUP($B$3,'Vendor Master'!A6:A15,'Vendor Master'!G6:G15,0) | D5: Total Debit | E5: =SUMIFS(Transactions!F:F,Transactions!C:C,$B$3) | G5: Total Credit | H5: =SUMIFS(Transactions!G:G,Transactions!C:C,$B$3)
A6: Closing Balance | B6: =B5+E5-H5
A8: Date | B8: Voucher No. | C8: Description | D8: Debit | E8: Credit | F8: Running Balance | G8: Reference | H8: Month | I8: Vendor ID
A9: =IFERROR(INDEX(Transactions!$A$6:$A$5000,AGGREGATE(15,6,(ROW(Transactions!$C$6:$C$5000)-ROW(Transactions!$C$6)+1)/(Transactions!$C$6:$C$5000=$B$3),ROWS($A$9:A9))),"") | B9: =IF($A9="","",INDEX(Transactions!$B$6:$B$5000,AGGREGATE(15,6,(ROW(Transactions!$C$6:$C$5000)-ROW(Transactions!$C$6)+1)/(Transactions!$C$6:$C$5000=$B$3),ROWS($A$9:A9)))) | C9: =IF($A9="","",INDEX(Transactions!$E$6:$E$5000,AGGREGATE(15,6,(ROW(Transactions!$C$6:$C$5000)-ROW(Transactions!$C$6)+1)/(Transactions!$C$6:$C$5000=$B$3),ROWS($A$9:A9)))) | D9: =IF($A9="","",INDEX(Transactions!$F$6:$F$5000,AGGREGATE(15,6,(ROW(Transactions!$C$6:$C$5000)-ROW(Transactions!$C$6)+1)/(Transactions!$C$6:$C$5000=$B$3),ROWS($A$9:A9)))) | E9: =IF($A9="","",INDEX(Transactions!$G$6:$G$5000,AGGREGATE(15,6,(ROW(Transactions!$C$6:$C$5000)-ROW(Transactions!$C$6)+1)/(Transactions!$C$6:$C$5000=$B$3),ROWS($A$9:A9)))) | F9: =IF($A9="","",$B$5+SUM($D$9:D9)-SUM($E$9:E9)) | G9: =IF($A9="","",INDEX(Transactions!$H$6:$H$5000,AGGREGATE(15,6,(ROW(Transactions!$C$6:$C$5000)-ROW(Transactions!$C$6)+1)/(Transactions!$C$6:$C$5000=$B$3),ROWS($A$9:A9)))) | H9: =IF($A9="","",TEXT($A9,"mmm-yyyy")) | I9: =IF($A9="","",$B$3)
A10: =IFERROR(INDEX(Transactions!$A$6:$A$5000,AGGREGATE(15,6,(ROW(Transactions!$C$6:$C$5000)-ROW(Transactions!$C$6)+1)/(Transactions!$C$6:$C$5000=$B$3),ROWS($A$9:A10))),"") | B10: =IF($A10="","",INDEX(Transactions!$B$6:$B$5000,AGGREGATE(15,6,(ROW(Transactions!$C$6:$C$5000)-ROW(Transactions!$C$6)+1)/(Transactions!$C$6:$C$5000=$B$3),ROWS($A$9:A10)))) | C10: =IF($A10="","",INDEX(Transactions!$E$6:$E$5000,AGGREGATE(15,6,(ROW(Transactions!$C$6:$C$5000)-ROW(Transactions!$C$6)+1)/(Transactions!$C$6:$C$5000=$B$3),ROWS($A$9:A10)))) | D10: =IF($A10="","",INDEX(Transactions!$F$6:$F$5000,AGGREGATE(15,6,(ROW(Transactions!$C$6:$C$5000)-ROW(Transactions!$C$6)+1)/(Transactions!$C$6:$C$5000=$B$3),ROWS($A$9:A10)))) | E10: =IF($A10="","",INDEX(Transactions!$G$6:$G$5000,AGGREGATE(15,6,(ROW(Transactions!$C$6:$C$5000)-ROW(Transactions!$C$6)+1)/(Transactions!$C$6:$C$5000=$B$3),ROWS($A$9:A10)))) | F10: =IF($A10="","",$B$5+SUM($D$9:D10)-SUM($E$9:E10)) | G10: =IF($A10="","",INDEX(Transactions!$H$6:$H$5000,AGGREGATE(15,6,(ROW(Transactions!$C$6:$C$5000)-ROW(Transactions!$C$6)+1)/(Transactions!$C$6:$C$5000=$B$3),ROWS($A$9:A10)))) | H10: =IF($A10="","",TEXT($A10,"mmm-yyyy")) | I10: =IF($A10="","",$B$3)
A11: =IFERROR(INDEX(Transactions!$A$6:$A$5000,AGGREGATE(15,6,(ROW(Transactions!$C$6:$C$5000)-ROW(Transactions!$C$6)+1)/(Transactions!$C$6:$C$5000=$B$3),ROWS($A$9:A11))),"") | B11: =IF($A11="","",INDEX(Transactions!$B$6:$B$5000,AGGREGATE(15,6,(ROW(Transactions!$C$6:$C$5000)-ROW(Transactions!$C$6)+1)/(Transactions!$C$6:$C$5000=$B$3),ROWS($A$9:A11)))) | C11: =IF($A11="","",INDEX(Transactions!$E$6:$E$5000,AGGREGATE(15,6,(ROW(Transactions!$C$6:$C$5000)-ROW(Transactions!$C$6)+1)/(Transactions!$C$6:$C$5000=$B$3),ROWS($A$9:A11)))) | D11: =IF($A11="","",INDEX(Transactions!$F$6:$F$5000,AGGREGATE(15,6,(ROW(Transactions!$C$6:$C$5000)-ROW(Transactions!$C$6)+1)/(Transactions!$C$6:$C$5000=$B$3),ROWS($A$9:A11)))) | E11: =IF($A11="","",INDEX(Transactions!$G$6:$G$5000,AGGREGATE(15,6,(ROW(Transactions!$C$6:$C$5000)-ROW(Transactions!$C$6)+1)/(Transactions!$C$6:$C$5000=$B$3),ROWS($A$9:A11)))) | F11: =IF($A11="","",$B$5+SUM($D$9:D11)-SUM($E$9:E11)) | G11: =IF($A11="","",INDEX(Transactions!$H$6:$H$5000,AGGREGATE(15,6,(ROW(Transactions!$C$6:$C$5000)-ROW(Transactions!$C$6)+1)/(Transactions!$C$6:$C$5000=$B$3),ROWS($A$9:A11)))) | H11: =IF($A11="","",TEXT($A11,"mmm-yyyy")) | I11: =IF($A11="","",$B$3)
A12: =IFERROR(INDEX(Transactions!$A$6:$A$5000,AGGREGATE(15,6,(ROW(Transactions!$C$6:$C$5000)-ROW(Transactions!$C$6)+1)/(Transactions!$C$6:$C$5000=$B$3),ROWS($A$9:A12))),"") | B12: =IF($A12="","",INDEX(Transactions!$B$6:$B$5000,AGGREGATE(15,6,(ROW(Transactions!$C$6:$C$5000)-ROW(Transactions!$C$6)+1)/(Transactions!$C$6:$C$5000=$B$3),ROWS($A$9:A12)))) | C12: =IF($A12="","",INDEX(Transactions!$E$6:$E$5000,AGGREGATE(15,6,(ROW(Transactions!$C$6:$C$5000)-ROW(Transactions!$C$6)+1)/(Transactions!$C$6:$C$5000=$B$3),ROWS($A$9:A12)))) | D12: =IF($A12="","",INDEX(Transactions!$F$6:$F$5000,AGGREGATE(15,6,(ROW(Transactions!$C$6:$C$5000)-ROW(Transactions!$C$6)+1)/(Transactions!$C$6:$C$5000=$B$3),ROWS($A$9:A12)))) | E12: =IF($A12="","",INDEX(Transactions!$G$6:$G$5000,AGGREGATE(15,6,(ROW(Transactions!$C$6:$C$5000)-ROW(Transactions!$C$6)+1)/(Transactions!$C$6:$C$5000=$B$3),ROWS($A$9:A12)))) | F12: =IF($A12="","",$B$5+SUM($D$9:D12)-SUM($E$9:E12)) | G12: =IF($A12="","",INDEX(Transactions!$H$6:$H$5000,AGGREGATE(15,6,(ROW(Transactions!$C$6:$C$5000)-ROW(Transactions!$C$6)+1)/(Transactions!$C$6:$C$5000=$B$3),ROWS($A$9:A12)))) | H12: =IF($A12="","",TEXT($A12,"mmm-yyyy")) | I12: =IF($A12="","",$B$3)
A13: =IFERROR(INDEX(Transactions!$A$6:$A$5000,AGGREGATE(15,6,(ROW(Transactions!$C$6:$C$5000)-ROW(Transactions!$C$6)+1)/(Transactions!$C$6:$C$5000=$B$3),ROWS($A$9:A13))),"") | B13: =IF($A13="","",INDEX(Transactions!$B$6:$B$5000,AGGREGATE(15,6,(ROW(Transactions!$C$6:$C$5000)-ROW(Transactions!$C$6)+1)/(Transactions!$C$6:$C$5000=$B$3),ROWS($A$9:A13)))) | C13: =IF($A13="","",INDEX(Transactions!$E$6:$E$5000,AGGREGATE(15,6,(ROW(Transactions!$C$6:$C$5000)-ROW(Transactions!$C$6)+1)/(Transactions!$C$6:$C$5000=$B$3),ROWS($A$9:A13)))) | D13: =IF($A13="","",INDEX(Transactions!$F$6:$F$5000,AGGREGATE(15,6,(ROW(Transactions!$C$6:$C$5000)-ROW(Transactions!$C$6)+1)/(Transactions!$C$6:$C$5000=$B$3),ROWS($A$9:A13)))) | E13: =IF($A13="","",INDEX(Transactions!$G$6:$G$5000,AGGREGATE(15,6,(ROW(Transactions!$C$6:$C$5000)-ROW(Transactions!$C$6)+1)/(Transactions!$C$6:$C$5000=$B$3),ROWS($A$9:A13)))) | F13: =IF($A13="","",$B$5+SUM($D$9:D13)-SUM($E$9:E13)) | G13: =IF($A13="","",INDEX(Transactions!$H$6:$H$5000,AGGREGATE(15,6,(ROW(Transactions!$C$6:$C$5000)-ROW(Transactions!$C$6)+1)/(Transactions!$C$6:$C$5000=$B$3),ROWS($A$9:A13)))) | H13: =IF($A13="","",TEXT($A13,"mmm-yyyy")) | I13: =IF($A13="","",$B$3)
A14: =IFERROR(INDEX(Transactions!$A$6:$A$5000,AGGREGATE(15,6,(ROW(Transactions!$C$6:$C$5000)-ROW(Transactions!$C$6)+1)/(Transactions!$C$6:$C$5000=$B$3),ROWS($A$9:A14))),"") | B14: =IF($A14="","",INDEX(Transactions!$B$6:$B$5000,AGGREGATE(15,6,(ROW(Transactions!$C$6:$C$5000)-ROW(Transactions!$C$6)+1)/(Transactions!$C$6:$C$5000=$B$3),ROWS($A$9:A14)))) | C14: =IF($A14="","",INDEX(Transactions!$E$6:$E$5000,AGGREGATE(15,6,(ROW(Transactions!$C$6:$C$5000)-ROW(Transactions!$C$6)+1)/(Transactions!$C$6:$C$5000=$B$3),ROWS($A$9:A14)))) | D14: =IF($A14="","",INDEX(Transactions!$F$6:$F$5000,AGGREGATE(15,6,(ROW(Transactions!$C$6:$C$5000)-ROW(Transactions!$C$6)+1)/(Transactions!$C$6:$C$5000=$B$3),ROWS($A$9:A14)))) | E14: =IF($A14="","",INDEX(Transactions!$G$6:$G$5000,AGGREGATE(15,6,(ROW(Transactions!$C$6:$C$5000)-ROW(Transactions!$C$6)+1)/(Transactions!$C$6:$C$5000=$B$3),ROWS($A$9:A14)))) | F14: =IF($A14="","",$B$5+SUM($D$9:D14)-SUM($E$9:E14)) | G14: =IF($A14="","",INDEX(Transactions!$H$6:$H$5000,AGGREGATE(15,6,(ROW(Transactions!$C$6:$C$5000)-ROW(Transactions!$C$6)+1)/(Transactions!$C$6:$C$5000=$B$3),ROWS($A$9:A14)))) | H14: =IF($A14="","",TEXT($A14,"mmm-yyyy")) | I14: =IF($A14="","",$B$3)
A15: =IFERROR(INDEX(Transactions!$A$6:$A$5000,AGGREGATE(15,6,(ROW(Transactions!$C$6:$C$5000)-ROW(Transactions!$C$6)+1)/(Transactions!$C$6:$C$5000=$B$3),ROWS($A$9:A15))),"") | B15: =IF($A15="","",INDEX(Transactions!$B$6:$B$5000,AGGREGATE(15,6,(ROW(Transactions!$C$6:$C$5000)-ROW(Transactions!$C$6)+1)/(Transactions!$C$6:$C$5000=$B$3),ROWS($A$9:A15)))) | C15: =IF($A15="","",INDEX(Transactions!$E$6:$E$5000,AGGREGATE(15,6,(ROW(Transactions!$C$6:$C$5000)-ROW(Transactions!$C$6)+1)/(Transactions!$C$6:$C$5000=$B$3),ROWS($A$9:A15)))) | D15: =IF($A15="","",INDEX(Transactions!$F$6:$F$5000,AGGREGATE(15,6,(ROW(Transactions!$C$6:$C$5000)-ROW(Transactions!$C$6)+1)/(Transactions!$C$6:$C$5000=$B$3),ROWS($A$9:A15)))) | E15: =IF($A15="","",INDEX(Transactions!$G$6:$G$5000,AGGREGATE(15,6,(ROW(Transactions!$C$6:$C$5000)-ROW(Transactions!$C$6)+1)/(Transactions!$C$6:$C$5000=$B$3),ROWS($A$9:A15)))) | F15: =IF($A15="","",$B$5+SUM($D$9:D15)-SUM($E$9:E15)) | G15: =IF($A15="","",INDEX(Transactions!$H$6:$H$5000,AGGREGATE(15,6,(ROW(Transactions!$C$6:$C$5000)-ROW(Transactions!$C$6)+1)/(Transactions!$C$6:$C$5000=$B$3),ROWS($A$9:A15)))) | H15: =IF($A15="","",TEXT($A15,"mmm-yyyy")) | I15: =IF($A15="","",$B$3)
A16: =IFERROR(INDEX(Transactions!$A$6:$A$5000,AGGREGATE(15,6,(ROW(Transactions!$C$6:$C$5000)-ROW(Transactions!$C$6)+1)/(Transactions!$C$6:$C$5000=$B$3),ROWS($A$9:A16))),"") | B16: =IF($A16="","",INDEX(Transactions!$B$6:$B$5000,AGGREGATE(15,6,(ROW(Transactions!$C$6:$C$5000)-ROW(Transactions!$C$6)+1)/(Transactions!$C$6:$C$5000=$B$3),ROWS($A$9:A16)))) | C16: =IF($A16="","",INDEX(Transactions!$E$6:$E$5000,AGGREGATE(15,6,(ROW(Transactions!$C$6:$C$5000)-ROW(Transactions!$C$6)+1)/(Transactions!$C$6:$C$5000=$B$3),ROWS($A$9:A16)))) | D16: =IF($A16="","",INDEX(Transactions!$F$6:$F$5000,AGGREGATE(15,6,(ROW(Transactions!$C$6:$C$5000)-ROW(Transactions!$C$6)+1)/(Transactions!$C$6:$C$5000=$B$3),ROWS($A$9:A16)))) | E16: =IF($A16="","",INDEX(Transactions!$G$6:$G$5000,AGGREGATE(15,6,(ROW(Transactions!$C$6:$C$5000)-ROW(Transactions!$C$6)+1)/(Transactions!$C$6:$C$5000=$B$3),ROWS($A$9:A16)))) | F16: =IF($A16="","",$B$5+SUM($D$9:D16)-SUM($E$9:E16)) | G16: =IF($A16="","",INDEX(Transactions!$H$6:$H$5000,AGGREGATE(15,6,(ROW(Transactions!$C$6:$C$5000)-ROW(Transactions!$C$6)+1)/(Transactions!$C$6:$C$5000=$B$3),ROWS($A$9:A16)))) | H16: =IF($A16="","",TEXT($A16,"mmm-yyyy")) | I16: =IF($A16="","",$B$3)
A17: =IFERROR(INDEX(Transactions!$A$6:$A$5000,AGGREGATE(15,6,(ROW(Transactions!$C$6:$C$5000)-ROW(Transactions!$C$6)+1)/(Transactions!$C$6:$C$5000=$B$3),ROWS($A$9:A17))),"") | B17: =IF($A17="","",INDEX(Transactions!$B$6:$B$5000,AGGREGATE(15,6,(ROW(Transactions!$C$6:$C$5000)-ROW(Transactions!$C$6)+1)/(Transactions!$C$6:$C$5000=$B$3),ROWS($A$9:A17)))) | C17: =IF($A17="","",INDEX(Transactions!$E$6:$E$5000,AGGREGATE(15,6,(ROW(Transactions!$C$6:$C$5000)-ROW(Transactions!$C$6)+1)/(Transactions!$C$6:$C$5000=$B$3),ROWS($A$9:A17)))) | D17: =IF($A17="","",INDEX(Transactions!$F$6:$F$5000,AGGREGATE(15,6,(ROW(Transactions!$C$6:$C$5000)-ROW(Transactions!$C$6)+1)/(Transactions!$C$6:$C$5000=$B$3),ROWS($A$9:A17)))) | E17: =IF($A17="","",INDEX(Transactions!$G$6:$G$5000,AGGREGATE(15,6,(ROW(Transactions!$C$6:$C$5000)-ROW(Transactions!$C$6)+1)/(Transactions!$C$6:$C$5000=$B$3),ROWS($A$9:A17)))) | F17: =IF($A17="","",$B$5+SUM($D$9:D17)-SUM($E$9:E17)) | G17: =IF($A17="","",INDEX(Transactions!$H$6:$H$5000,AGGREGATE(15,6,(ROW(Transactions!$C$6:$C$5000)-ROW(Transactions!$C$6)+1)/(Transactions!$C$6:$C$5000=$B$3),ROWS($A$9:A17)))) | H17: =IF($A17="","",TEXT($A17,"mmm-yyyy")) | I17: =IF($A17="","",$B$3)
A18: =IFERROR(INDEX(Transactions!$A$6:$A$5000,AGGREGATE(15,6,(ROW(Transactions!$C$6:$C$5000)-ROW(Transactions!$C$6)+1)/(Transactions!$C$6:$C$5000=$B$3),ROWS($A$9:A18))),"") | B18: =IF($A18="","",INDEX(Transactions!$B$6:$B$5000,AGGREGATE(15,6,(ROW(Transactions!$C$6:$C$5000)-ROW(Transactions!$C$6)+1)/(Transactions!$C$6:$C$5000=$B$3),ROWS($A$9:A18)))) | C18: =IF($A18="","",INDEX(Transactions!$E$6:$E$5000,AGGREGATE(15,6,(ROW(Transactions!$C$6:$C$5000)-ROW(Transactions!$C$6)+1)/(Transactions!$C$6:$C$5000=$B$3),ROWS($A$9:A18)))) | D18: =IF($A18="","",INDEX(Transactions!$F$6:$F$5000,AGGREGATE(15,6,(ROW(Transactions!$C$6:$C$5000)-ROW(Transactions!$C$6)+1)/(Transactions!$C$6:$C$5000=$B$3),ROWS($A$9:A18)))) | E18: =IF($A18="","",INDEX(Transactions!$G$6:$G$5000,AGGREGATE(15,6,(ROW(Transactions!$C$6:$C$5000)-ROW(Transactions!$C$6)+1)/(Transactions!$C$6:$C$5000=$B$3),ROWS($A$9:A18)))) | F18: =IF($A18="","",$B$5+SUM($D$9:D18)-SUM($E$9:E18)) | G18: =IF($A18="","",INDEX(Transactions!$H$6:$H$5000,AGGREGATE(15,6,(ROW(Transactions!$C$6:$C$5000)-ROW(Transactions!$C$6)+1)/(Transactions!$C$6:$C$5000=$B$3),ROWS($A$9:A18)))) | H18: =IF($A18="","",TEXT($A18,"mmm-yyyy")) | I18: =IF($A18="","",$B$3)
A19: =IFERROR(INDEX(Transactions!$A$6:$A$5000,AGGREGATE(15,6,(ROW(Transactions!$C$6:$C$5000)-ROW(Transactions!$C$6)+1)/(Transactions!$C$6:$C$5000=$B$3),ROWS($A$9:A19))),"") | B19: =IF($A19="","",INDEX(Transactions!$B$6:$B$5000,AGGREGATE(15,6,(ROW(Transactions!$C$6:$C$5000)-ROW(Transactions!$C$6)+1)/(Transactions!$C$6:$C$5000=$B$3),ROWS($A$9:A19)))) | C19: =IF($A19="","",INDEX(Transactions!$E$6:$E$5000,AGGREGATE(15,6,(ROW(Transactions!$C$6:$C$5000)-ROW(Transactions!$C$6)+1)/(Transactions!$C$6:$C$5000=$B$3),ROWS($A$9:A19)))) | D19: =IF($A19="","",INDEX(Transactions!$F$6:$F$5000,AGGREGATE(15,6,(ROW(Transactions!$C$6:$C$5000)-ROW(Transactions!$C$6)+1)/(Transactions!$C$6:$C$5000=$B$3),ROWS($A$9:A19)))) | E19: =IF($A19="","",INDEX(Transactions!$G$6:$G$5000,AGGREGATE(15,6,(ROW(Transactions!$C$6:$C$5000)-ROW(Transactions!$C$6)+1)/(Transactions!$C$6:$C$5000=$B$3),ROWS($A$9:A19)))) | F19: =IF($A19="","",$B$5+SUM($D$9:D19)-SUM($E$9:E19)) | G19: =IF($A19="","",INDEX(Transactions!$H$6:$H$5000,AGGREGATE(15,6,(ROW(Transactions!$C$6:$C$5000)-ROW(Transactions!$C$6)+1)/(Transactions!$C$6:$C$5000=$B$3),ROWS($A$9:A19)))) | H19: =IF($A19="","",TEXT($A19,"mmm-yyyy")) | I19: =IF($A19="","",$B$3)
A20: =IFERROR(INDEX(Transactions!$A$6:$A$5000,AGGREGATE(15,6,(ROW(Transactions!$C$6:$C$5000)-ROW(Transactions!$C$6)+1)/(Transactions!$C$6:$C$5000=$B$3),ROWS($A$9:A20))),"") | B20: =IF($A20="","",INDEX(Transactions!$B$6:$B$5000,AGGREGATE(15,6,(ROW(Transactions!$C$6:$C$5000)-ROW(Transactions!$C$6)+1)/(Transactions!$C$6:$C$5000=$B$3),ROWS($A$9:A20)))) | C20: =IF($A20="","",INDEX(Transactions!$E$6:$E$5000,AGGREGATE(15,6,(ROW(Transactions!$C$6:$C$5000)-ROW(Transactions!$C$6)+1)/(Transactions!$C$6:$C$5000=$B$3),ROWS($A$9:A20)))) | D20: =IF($A20="","",INDEX(Transactions!$F$6:$F$5000,AGGREGATE(15,6,(ROW(Transactions!$C$6:$C$5000)-ROW(Transactions!$C$6)+1)/(Transactions!$C$6:$C$5000=$B$3),ROWS($A$9:A20)))) | E20: =IF($A20="","",INDEX(Transactions!$G$6:$G$5000,AGGREGATE(15,6,(ROW(Transactions!$C$6:$C$5000)-ROW(Transactions!$C$6)+1)/(Transactions!$C$6:$C$5000=$B$3),ROWS($A$9:A20)))) | F20: =IF($A20="","",$B$5+SUM($D$9:D20)-SUM($E$9:E20)) | G20: =IF($A20="","",INDEX(Transactions!$H$6:$H$5000,AGGREGATE(15,6,(ROW(Transactions!$C$6:$C$5000)-ROW(Transactions!$C$6)+1)/(Transactions!$C$6:$C$5000=$B$3),ROWS($A$9:A20)))) | H20: =IF($A20="","",TEXT($A20,"mmm-yyyy")) | I20: =IF($A20="","",$B$3)
... A108: =IFERROR(INDEX(Transactions!$A$6:$A$5000,AGGREGATE(15,6,(ROW(Transactions!$C$6:$C$5000)-ROW(Transactions!$C$6)+1)/(Transactions!$C$6:$C$5000=$B$3),ROWS($A$9:A108))),"") | B108: =IF($A108="","",INDEX(Transactions!$B$6:$B$5000,AGGREGATE(15,6,(ROW(Transactions!$C$6:$C$5000)-ROW(Transactions!$C$6)+1)/(Transactions!$C$6:$C$5000=$B$3),ROWS($A$9:A108)))) | C108: =IF($A108="","",INDEX(Transactions!$E$6:$E$5000,AGGREGATE(15,6,(ROW(Transactions!$C$6:$C$5000)-ROW(Transactions!$C$6)+1)/(Transactions!$C$6:$C$5000=$B$3),ROWS($A$9:A108)))) | D108: =IF($A108="","",INDEX(Transactions!$F$6:$F$5000,AGGREGATE(15,6,(ROW(Transactions!$C$6:$C$5000)-ROW(Transactions!$C$6)+1)/(Transactions!$C$6:$C$5000=$B$3),ROWS($A$9:A108)))) | E108: =IF($A108="","",INDEX(Transactions!$G$6:$G$5000,AGGREGATE(15,6,(ROW(Transactions!$C$6:$C$5000)-ROW(Transactions!$C$6)+1)/(Transactions!$C$6:$C$5000=$B$3),ROWS($A$9:A108)))) | F108: =IF($A108="","",$B$5+SUM($D$9:D108)-SUM($E$9:E108)) | G108: =IF($A108="","",INDEX(Transactions!$H$6:$H$5000,AGGREGATE(15,6,(ROW(Transactions!$C$6:$C$5000)-ROW(Transactions!$C$6)+1)/(Transactions!$C$6:$C$5000=$B$3),ROWS($A$9:A108)))) | H108: =IF($A108="","",TEXT($A108,"mmm-yyyy")) | I108: =IF($A108="","",$B$3)

Sheet V002
A1: PAK TEXTILE TRADERS — VENDOR LEDGER
A2: Vendor ID: V002 | Category: Textile | Linked to Transactions
A3: Vendor ID | B3: V002 | D3: ← BACK TO LEDGER INDEX
A5: Opening Balance | B5: =XLOOKUP($B$3,'Vendor Master'!A6:A15,'Vendor Master'!G6:G15,0) | D5: Total Debit | E5: =SUMIFS(Transactions!F:F,Transactions!C:C,$B$3) | G5: Total Credit | H5: =SUMIFS(Transactions!G:G,Transactions!C:C,$B$3)
A6: Closing Balance | B6: =B5+E5-H5
A8: Date | B8: Voucher No. | C8: Description | D8: Debit | E8: Credit | F8: Running Balance | G8: Reference | H8: Month | I8: Vendor ID
A9: =IFERROR(INDEX(Transactions!$A$6:$A$5000,AGGREGATE(15,6,(ROW(Transactions!$C$6:$C$5000)-ROW(Transactions!$C$6)+1)/(Transactions!$C$6:$C$5000=$B$3),ROWS($A$9:A9))),"") | B9: =IF($A9="","",INDEX(Transactions!$B$6:$B$5000,AGGREGATE(15,6,(ROW(Transactions!$C$6:$C$5000)-ROW(Transactions!$C$6)+1)/(Transactions!$C$6:$C$5000=$B$3),ROWS($A$9:A9)))) | C9: =IF($A9="","",INDEX(Transactions!$E$6:$E$5000,AGGREGATE(15,6,(ROW(Transactions!$C$6:$C$5000)-ROW(Transactions!$C$6)+1)/(Transactions!$C$6:$C$5000=$B$3),ROWS($A$9:A9)))) | D9: =IF($A9="","",INDEX(Transactions!$F$6:$F$5000,AGGREGATE(15,6,(ROW(Transactions!$C$6:$C$5000)-ROW(Transactions!$C$6)+1)/(Transactions!$C$6:$C$5000=$B$3),ROWS($A$9:A9)))) | E9: =IF($A9="","",INDEX(Transactions!$G$6:$G$5000,AGGREGATE(15,6,(ROW(Transactions!$C$6:$C$5000)-ROW(Transactions!$C$6)+1)/(Transactions!$C$6:$C$5000=$B$3),ROWS($A$9:A9)))) | F9: =IF($A9="","",$B$5+SUM($D$9:D9)-SUM($E$9:E9)) | G9: =IF($A9="","",INDEX(Transactions!$H$6:$H$5000,AGGREGATE(15,6,(ROW(Transactions!$C$6:$C$5000)-ROW(Transactions!$C$6)+1)/(Transactions!$C$6:$C$5000=$B$3),ROWS($A$9:A9)))) | H9: =IF($A9="","",TEXT($A9,"mmm-yyyy")) | I9: =IF($A9="","",$B$3)
A10: =IFERROR(INDEX(Transactions!$A$6:$A$5000,AGGREGATE(15,6,(ROW(Transactions!$C$6:$C$5000)-ROW(Transactions!$C$6)+1)/(Transactions!$C$6:$C$5000=$B$3),ROWS($A$9:A10))),"") | B10: =IF($A10="","",INDEX(Transactions!$B$6:$B$5000,AGGREGATE(15,6,(ROW(Transactions!$C$6:$C$5000)-ROW(Transactions!$C$6)+1)/(Transactions!$C$6:$C$5000=$B$3),ROWS($A$9:A10)))) | C10: =IF($A10="","",INDEX(Transactions!$E$6:$E$5000,AGGREGATE(15,6,(ROW(Transactions!$C$6:$C$5000)-ROW(Transactions!$C$6)+1)/(Transactions!$C$6:$C$5000=$B$3),ROWS($A$9:A10)))) | D10: =IF($A10="","",INDEX(Transactions!$F$6:$F$5000,AGGREGATE(15,6,(ROW(Transactions!$C$6:$C$5000)-ROW(Transactions!$C$6)+1)/(Transactions!$C$6:$C$5000=$B$3),ROWS($A$9:A10)))) | E10: =IF($A10="","",INDEX(Transactions!$G$6:$G$5000,AGGREGATE(15,6,(ROW(Transactions!$C$6:$C$5000)-ROW(Transactions!$C$6)+1)/(Transactions!$C$6:$C$5000=$B$3),ROWS($A$9:A10)))) | F10: =IF($A10="","",$B$5+SUM($D$9:D10)-SUM($E$9:E10)) | G10: =IF($A10="","",INDEX(Transactions!$H$6:$H$5000,AGGREGATE(15,6,(ROW(Transactions!$C$6:$C$5000)-ROW(Transactions!$C$6)+1)/(Transactions!$C$6:$C$5000=$B$3),ROWS($A$9:A10)))) | H10: =IF($A10="","",TEXT($A10,"mmm-yyyy")) | I10: =IF($A10="","",$B$3)
A11: =IFERROR(INDEX(Transactions!$A$6:$A$5000,AGGREGATE(15,6,(ROW(Transactions!$C$6:$C$5000)-ROW(Transactions!$C$6)+1)/(Transactions!$C$6:$C$5000=$B$3),ROWS($A$9:A11))),"") | B11: =IF($A11="","",INDEX(Transactions!$B$6:$B$5000,AGGREGATE(15,6,(ROW(Transactions!$C$6:$C$5000)-ROW(Transactions!$C$6)+1)/(Transactions!$C$6:$C$5000=$B$3),ROWS($A$9:A11)))) | C11: =IF($A11="","",INDEX(Transactions!$E$6:$E$5000,AGGREGATE(15,6,(ROW(Transactions!$C$6:$C$5000)-ROW(Transactions!$C$6)+1)/(Transactions!$C$6:$C$5000=$B$3),ROWS($A$9:A11)))) | D11: =IF($A11="","",INDEX(Transactions!$F$6:$F$5000,AGGREGATE(15,6,(ROW(Transactions!$C$6:$C$5000)-ROW(Transactions!$C$6)+1)/(Transactions!$C$6:$C$5000=$B$3),ROWS($A$9:A11)))) | E11: =IF($A11="","",INDEX(Transactions!$G$6:$G$5000,AGGREGATE(15,6,(ROW(Transactions!$C$6:$C$5000)-ROW(Transactions!$C$6)+1)/(Transactions!$C$6:$C$5000=$B$3),ROWS($A$9:A11)))) | F11: =IF($A11="","",$B$5+SUM($D$9:D11)-SUM($E$9:E11)) | G11: =IF($A11="","",INDEX(Transactions!$H$6:$H$5000,AGGREGATE(15,6,(ROW(Transactions!$C$6:$C$5000)-ROW(Transactions!$C$6)+1)/(Transactions!$C$6:$C$5000=$B$3),ROWS($A$9:A11)))) | H11: =IF($A11="","",TEXT($A11,"mmm-yyyy")) | I11: =IF($A11="","",$B$3)
A12: =IFERROR(INDEX(Transactions!$A$6:$A$5000,AGGREGATE(15,6,(ROW(Transactions!$C$6:$C$5000)-ROW(Transactions!$C$6)+1)/(Transactions!$C$6:$C$5000=$B$3),ROWS($A$9:A12))),"") | B12: =IF($A12="","",INDEX(Transactions!$B$6:$B$5000,AGGREGATE(15,6,(ROW(Transactions!$C$6:$C$5000)-ROW(Transactions!$C$6)+1)/(Transactions!$C$6:$C$5000=$B$3),ROWS($A$9:A12)))) | C12: =IF($A12="","",INDEX(Transactions!$E$6:$E$5000,AGGREGATE(15,6,(ROW(Transactions!$C$6:$C$5000)-ROW(Transactions!$C$6)+1)/(Transactions!$C$6:$C$5000=$B$3),ROWS($A$9:A12)))) | D12: =IF($A12="","",INDEX(Transactions!$F$6:$F$5000,AGGREGATE(15,6,(ROW(Transactions!$C$6:$C$5000)-ROW(Transactions!$C$6)+1)/(Transactions!$C$6:$C$5000=$B$3),ROWS($A$9:A12)))) | E12: =IF($A12="","",INDEX(Transactions!$G$6:$G$5000,AGGREGATE(15,6,(ROW(Transactions!$C$6:$C$5000)-ROW(Transactions!$C$6)+1)/(Transactions!$C$6:$C$5000=$B$3),ROWS($A$9:A12)))) | F12: =IF($A12="","",$B$5+SUM($D$9:D12)-SUM($E$9:E12)) | G12: =IF($A12="","",INDEX(Transactions!$H$6:$H$5000,AGGREGATE(15,6,(ROW(Transactions!$C$6:$C$5000)-ROW(Transactions!$C$6)+1)/(Transactions!$C$6:$C$5000=$B$3),ROWS($A$9:A12)))) | H12: =IF($A12="","",TEXT($A12,"mmm-yyyy")) | I12: =IF($A12="","",$B$3)
A13: =IFERROR(INDEX(Transactions!$A$6:$A$5000,AGGREGATE(15,6,(ROW(Transactions!$C$6:$C$5000)-ROW(Transactions!$C$6)+1)/(Transactions!$C$6:$C$5000=$B$3),ROWS($A$9:A13))),"") | B13: =IF($A13="","",INDEX(Transactions!$B$6:$B$5000,AGGREGATE(15,6,(ROW(Transactions!$C$6:$C$5000)-ROW(Transactions!$C$6)+1)/(Transactions!$C$6:$C$5000=$B$3),ROWS($A$9:A13)))) | C13: =IF($A13="","",INDEX(Transactions!$E$6:$E$5000,AGGREGATE(15,6,(ROW(Transactions!$C$6:$C$5000)-ROW(Transactions!$C$6)+1)/(Transactions!$C$6:$C$5000=$B$3),ROWS($A$9:A13)))) | D13: =IF($A13="","",INDEX(Transactions!$F$6:$F$5000,AGGREGATE(15,6,(ROW(Transactions!$C$6:$C$5000)-ROW(Transactions!$C$6)+1)/(Transactions!$C$6:$C$5000=$B$3),ROWS($A$9:A13)))) | E13: =IF($A13="","",INDEX(Transactions!$G$6:$G$5000,AGGREGATE(15,6,(ROW(Transactions!$C$6:$C$5000)-ROW(Transactions!$C$6)+1)/(Transactions!$C$6:$C$5000=$B$3),ROWS($A$9:A13)))) | F13: =IF($A13="","",$B$5+SUM($D$9:D13)-SUM($E$9:E13)) | G13: =IF($A13="","",INDEX(Transactions!$H$6:$H$5000,AGGREGATE(15,6,(ROW(Transactions!$C$6:$C$5000)-ROW(Transactions!$C$6)+1)/(Transactions!$C$6:$C$5000=$B$3),ROWS($A$9:A13)))) | H13: =IF($A13="","",TEXT($A13,"mmm-yyyy")) | I13: =IF($A13="","",$B$3)
A14: =IFERROR(INDEX(Transactions!$A$6:$A$5000,AGGREGATE(15,6,(ROW(Transactions!$C$6:$C$5000)-ROW(Transactions!$C$6)+1)/(Transactions!$C$6:$C$5000=$B$3),ROWS($A$9:A14))),"") | B14: =IF($A14="","",INDEX(Transactions!$B$6:$B$5000,AGGREGATE(15,6,(ROW(Transactions!$C$6:$C$5000)-ROW(Transactions!$C$6)+1)/(Transactions!$C$6:$C$5000=$B$3),ROWS($A$9:A14)))) | C14: =IF($A14="","",INDEX(Transactions!$E$6:$E$5000,AGGREGATE(15,6,(ROW(Transactions!$C$6:$C$5000)-ROW(Transactions!$C$6)+1)/(Transactions!$C$6:$C$5000=$B$3),ROWS($A$9:A14)))) | D14: =IF($A14="","",INDEX(Transactions!$F$6:$F$5000,AGGREGATE(15,6,(ROW(Transactions!$C$6:$C$5000)-ROW(Transactions!$C$6)+1)/(Transactions!$C$6:$C$5000=$B$3),ROWS($A$9:A14)))) | E14: =IF($A14="","",INDEX(Transactions!$G$6:$G$5000,AGGREGATE(15,6,(ROW(Transactions!$C$6:$C$5000)-ROW(Transactions!$C$6)+1)/(Transactions!$C$6:$C$5000=$B$3),ROWS($A$9:A14)))) | F14: =IF($A14="","",$B$5+SUM($D$9:D14)-SUM($E$9:E14)) | G14: =IF($A14="","",INDEX(Transactions!$H$6:$H$5000,AGGREGATE(15,6,(ROW(Transactions!$C$6:$C$5000)-ROW(Transactions!$C$6)+1)/(Transactions!$C$6:$C$5000=$B$3),ROWS($A$9:A14)))) | H14: =IF($A14="","",TEXT($A14,"mmm-yyyy")) | I14: =IF($A14="","",$B$3)
A15: =IFERROR(INDEX(Transactions!$A$6:$A$5000,AGGREGATE(15,6,(ROW(Transactions!$C$6:$C$5000)-ROW(Transactions!$C$6)+1)/(Transactions!$C$6:$C$5000=$B$3),ROWS($A$9:A15))),"") | B15: =IF($A15="","",INDEX(Transactions!$B$6:$B$5000,AGGREGATE(15,6,(ROW(Transactions!$C$6:$C$5000)-ROW(Transactions!$C$6)+1)/(Transactions!$C$6:$C$5000=$B$3),ROWS($A$9:A15)))) | C15: =IF($A15="","",INDEX(Transactions!$E$6:$E$5000,AGGREGATE(15,6,(ROW(Transactions!$C$6:$C$5000)-ROW(Transactions!$C$6)+1)/(Transactions!$C$6:$C$5000=$B$3),ROWS($A$9:A15)))) | D15: =IF($A15="","",INDEX(Transactions!$F$6:$F$5000,AGGREGATE(15,6,(ROW(Transactions!$C$6:$C$5000)-ROW(Transactions!$C$6)+1)/(Transactions!$C$6:$C$5000=$B$3),ROWS($A$9:A15)))) | E15: =IF($A15="","",INDEX(Transactions!$G$6:$G$5000,AGGREGATE(15,6,(ROW(Transactions!$C$6:$C$5000)-ROW(Transactions!$C$6)+1)/(Transactions!$C$6:$C$5000=$B$3),ROWS($A$9:A15)))) | F15: =IF($A15="","",$B$5+SUM($D$9:D15)-SUM($E$9:E15)) | G15: =IF($A15="","",INDEX(Transactions!$H$6:$H$5000,AGGREGATE(15,6,(ROW(Transactions!$C$6:$C$5000)-ROW(Transactions!$C$6)+1)/(Transactions!$C$6:$C$5000=$B$3),ROWS($A$9:A15)))) | H15: =IF($A15="","",TEXT($A15,"mmm-yyyy")) | I15: =IF($A15="","",$B$3)
A16: =IFERROR(INDEX(Transactions!$A$6:$A$5000,AGGREGATE(15,6,(ROW(Transactions!$C$6:$C$5000)-ROW(Transactions!$C$6)+1)/(Transactions!$C$6:$C$5000=$B$3),ROWS($A$9:A16))),"") | B16: =IF($A16="","",INDEX(Transactions!$B$6:$B$5000,AGGREGATE(15,6,(ROW(Transactions!$C$6:$C$5000)-ROW(Transactions!$C$6)+1)/(Transactions!$C$6:$C$5000=$B$3),ROWS($A$9:A16)))) | C16: =IF($A16="","",INDEX(Transactions!$E$6:$E$5000,AGGREGATE(15,6,(ROW(Transactions!$C$6:$C$5000)-ROW(Transactions!$C$6)+1)/(Transactions!$C$6:$C$5000=$B$3),ROWS($A$9:A16)))) | D16: =IF($A16="","",INDEX(Transactions!$F$6:$F$5000,AGGREGATE(15,6,(ROW(Transactions!$C$6:$C$5000)-ROW(Transactions!$C$6)+1)/(Transactions!$C$6:$C$5000=$B$3),ROWS($A$9:A16)))) | E16: =IF($A16="","",INDEX(Transactions!$G$6:$G$5000,AGGREGATE(15,6,(ROW(Transactions!$C$6:$C$5000)-ROW(Transactions!$C$6)+1)/(Transactions!$C$6:$C$5000=$B$3),ROWS($A$9:A16)))) | F16: =IF($A16="","",$B$5+SUM($D$9:D16)-SUM($E$9:E16)) | G16: =IF($A16="","",INDEX(Transactions!$H$6:$H$5000,AGGREGATE(15,6,(ROW(Transactions!$C$6:$C$5000)-ROW(Transactions!$C$6)+1)/(Transactions!$C$6:$C$5000=$B$3),ROWS($A$9:A16)))) | H16: =IF($A16="","",TEXT($A16,"mmm-yyyy")) | I16: =IF($A16="","",$B$3)
A17: =IFERROR(INDEX(Transactions!$A$6:$A$5000,AGGREGATE(15,6,(ROW(Transactions!$C$6:$C$5000)-ROW(Transactions!$C$6)+1)/(Transactions!$C$6:$C$5000=$B$3),ROWS($A$9:A17))),"") | B17: =IF($A17="","",INDEX(Transactions!$B$6:$B$5000,AGGREGATE(15,6,(ROW(Transactions!$C$6:$C$5000)-ROW(Transactions!$C$6)+1)/(Transactions!$C$6:$C$5000=$B$3),ROWS($A$9:A17)))) | C17: =IF($A17="","",INDEX(Transactions!$E$6:$E$5000,AGGREGATE(15,6,(ROW(Transactions!$C$6:$C$5000)-ROW(Transactions!$C$6)+1)/(Transactions!$C$6:$C$5000=$B$3),ROWS($A$9:A17)))) | D17: =IF($A17="","",INDEX(Transactions!$F$6:$F$5000,AGGREGATE(15,6,(ROW(Transactions!$C$6:$C$5000)-ROW(Transactions!$C$6)+1)/(Transactions!$C$6:$C$5000=$B$3),ROWS($A$9:A17)))) | E17: =IF($A17="","",INDEX(Transactions!$G$6:$G$5000,AGGREGATE(15,6,(ROW(Transactions!$C$6:$C$5000)-ROW(Transactions!$C$6)+1)/(Transactions!$C$6:$C$5000=$B$3),ROWS($A$9:A17)))) | F17: =IF($A17="","",$B$5+SUM($D$9:D17)-SUM($E$9:E17)) | G17: =IF($A17="","",INDEX(Transactions!$H$6:$H$5000,AGGREGATE(15,6,(ROW(Transactions!$C$6:$C$5000)-ROW(Transactions!$C$6)+1)/(Transactions!$C$6:$C$5000=$B$3),ROWS($A$9:A17)))) | H17: =IF($A17="","",TEXT($A17,"mmm-yyyy")) | I17: =IF($A17="","",$B$3)
A18: =IFERROR(INDEX(Transactions!$A$6:$A$5000,AGGREGATE(15,6,(ROW(Transactions!$C$6:$C$5000)-ROW(Transactions!$C$6)+1)/(Transactions!$C$6:$C$5000=$B$3),ROWS($A$9:A18))),"") | B18: =IF($A18="","",INDEX(Transactions!$B$6:$B$5000,AGGREGATE(15,6,(ROW(Transactions!$C$6:$C$5000)-ROW(Transactions!$C$6)+1)/(Transactions!$C$6:$C$5000=$B$3),ROWS($A$9:A18)))) | C18: =IF($A18="","",INDEX(Transactions!$E$6:$E$5000,AGGREGATE(15,6,(ROW(Transactions!$C$6:$C$5000)-ROW(Transactions!$C$6)+1)/(Transactions!$C$6:$C$5000=$B$3),ROWS($A$9:A18)))) | D18: =IF($A18="","",INDEX(Transactions!$F$6:$F$5000,AGGREGATE(15,6,(ROW(Transactions!$C$6:$C$5000)-ROW(Transactions!$C$6)+1)/(Transactions!$C$6:$C$5000=$B$3),ROWS($A$9:A18)))) | E18: =IF($A18="","",INDEX(Transactions!$G$6:$G$5000,AGGREGATE(15,6,(ROW(Transactions!$C$6:$C$5000)-ROW(Transactions!$C$6)+1)/(Transactions!$C$6:$C$5000=$B$3),ROWS($A$9:A18)))) | F18: =IF($A18="","",$B$5+SUM($D$9:D18)-SUM($E$9:E18)) | G18: =IF($A18="","",INDEX(Transactions!$H$6:$H$5000,AGGREGATE(15,6,(ROW(Transactions!$C$6:$C$5000)-ROW(Transactions!$C$6)+1)/(Transactions!$C$6:$C$5000=$B$3),ROWS($A$9:A18)))) | H18: =IF($A18="","",TEXT($A18,"mmm-yyyy")) | I18: =IF($A18="","",$B$3)
A19: =IFERROR(INDEX(Transactions!$A$6:$A$5000,AGGREGATE(15,6,(ROW(Transactions!$C$6:$C$5000)-ROW(Transactions!$C$6)+1)/(Transactions!$C$6:$C$5000=$B$3),ROWS($A$9:A19))),"") | B19: =IF($A19="","",INDEX(Transactions!$B$6:$B$5000,AGGREGATE(15,6,(ROW(Transactions!$C$6:$C$5000)-ROW(Transactions!$C$6)+1)/(Transactions!$C$6:$C$5000=$B$3),ROWS($A$9:A19)))) | C19: =IF($A19="","",INDEX(Transactions!$E$6:$E$5000,AGGREGATE(15,6,(ROW(Transactions!$C$6:$C$5000)-ROW(Transactions!$C$6)+1)/(Transactions!$C$6:$C$5000=$B$3),ROWS($A$9:A19)))) | D19: =IF($A19="","",INDEX(Transactions!$F$6:$F$5000,AGGREGATE(15,6,(ROW(Transactions!$C$6:$C$5000)-ROW(Transactions!$C$6)+1)/(Transactions!$C$6:$C$5000=$B$3),ROWS($A$9:A19)))) | E19: =IF($A19="","",INDEX(Transactions!$G$6:$G$5000,AGGREGATE(15,6,(ROW(Transactions!$C$6:$C$5000)-ROW(Transactions!$C$6)+1)/(Transactions!$C$6:$C$5000=$B$3),ROWS($A$9:A19)))) | F19: =IF($A19="","",$B$5+SUM($D$9:D19)-SUM($E$9:E19)) | G19: =IF($A19="","",INDEX(Transactions!$H$6:$H$5000,AGGREGATE(15,6,(ROW(Transactions!$C$6:$C$5000)-ROW(Transactions!$C$6)+1)/(Transactions!$C$6:$C$5000=$B$3),ROWS($A$9:A19)))) | H19: =IF($A19="","",TEXT($A19,"mmm-yyyy")) | I19: =IF($A19="","",$B$3)
A20: =IFERROR(INDEX(Transactions!$A$6:$A$5000,AGGREGATE(15,6,(ROW(Transactions!$C$6:$C$5000)-ROW(Transactions!$C$6)+1)/(Transactions!$C$6:$C$5000=$B$3),ROWS($A$9:A20))),"") | B20: =IF($A20="","",INDEX(Transactions!$B$6:$B$5000,AGGREGATE(15,6,(ROW(Transactions!$C$6:$C$5000)-ROW(Transactions!$C$6)+1)/(Transactions!$C$6:$C$5000=$B$3),ROWS($A$9:A20)))) | C20: =IF($A20="","",INDEX(Transactions!$E$6:$E$5000,AGGREGATE(15,6,(ROW(Transactions!$C$6:$C$5000)-ROW(Transactions!$C$6)+1)/(Transactions!$C$6:$C$5000=$B$3),ROWS($A$9:A20)))) | D20: =IF($A20="","",INDEX(Transactions!$F$6:$F$5000,AGGREGATE(15,6,(ROW(Transactions!$C$6:$C$5000)-ROW(Transactions!$C$6)+1)/(Transactions!$C$6:$C$5000=$B$3),ROWS($A$9:A20)))) | E20: =IF($A20="","",INDEX(Transactions!$G$6:$G$5000,AGGREGATE(15,6,(ROW(Transactions!$C$6:$C$5000)-ROW(Transactions!$C$6)+1)/(Transactions!$C$6:$C$5000=$B$3),ROWS($A$9:A20)))) | F20: =IF($A20="","",$B$5+SUM($D$9:D20)-SUM($E$9:E20)) | G20: =IF($A20="","",INDEX(Transactions!$H$6:$H$5000,AGGREGATE(15,6,(ROW(Transactions!$C$6:$C$5000)-ROW(Transactions!$C$6)+1)/(Transactions!$C$6:$C$5000=$B$3),ROWS($A$9:A20)))) | H20: =IF($A20="","",TEXT($A20,"mmm-yyyy")) | I20: =IF($A20="","",$B$3)
... A108: =IFERROR(INDEX(Transactions!$A$6:$A$5000,AGGREGATE(15,6,(ROW(Transactions!$C$6:$C$5000)-ROW(Transactions!$C$6)+1)/(Transactions!$C$6:$C$5000=$B$3),ROWS($A$9:A108))),"") | B108: =IF($A108="","",INDEX(Transactions!$B$6:$B$5000,AGGREGATE(15,6,(ROW(Transactions!$C$6:$C$5000)-ROW(Transactions!$C$6)+1)/(Transactions!$C$6:$C$5000=$B$3),ROWS($A$9:A108)))) | C108: =IF($A108="","",INDEX(Transactions!$E$6:$E$5000,AGGREGATE(15,6,(ROW(Transactions!$C$6:$C$5000)-ROW(Transactions!$C$6)+1)/(Transactions!$C$6:$C$5000=$B$3),ROWS($A$9:A108)))) | D108: =IF($A108="","",INDEX(Transactions!$F$6:$F$5000,AGGREGATE(15,6,(ROW(Transactions!$C$6:$C$5000)-ROW(Transactions!$C$6)+1)/(Transactions!$C$6:$C$5000=$B$3),ROWS($A$9:A108)))) | E108: =IF($A108="","",INDEX(Transactions!$G$6:$G$5000,AGGREGATE(15,6,(ROW(Transactions!$C$6:$C$5000)-ROW(Transactions!$C$6)+1)/(Transactions!$C$6:$C$5000=$B$3),ROWS($A$9:A108)))) | F108: =IF($A108="","",$B$5+SUM($D$9:D108)-SUM($E$9:E108)) | G108: =IF($A108="","",INDEX(Transactions!$H$6:$H$5000,AGGREGATE(15,6,(ROW(Transactions!$C$6:$C$5000)-ROW(Transactions!$C$6)+1)/(Transactions!$C$6:$C$5000=$B$3),ROWS($A$9:A108)))) | H108: =IF($A108="","",TEXT($A108,"mmm-yyyy")) | I108: =IF($A108="","",$B$3)

Sheet V003
A1: FAISAL ENGINEERING WORKS — VENDOR LEDGER
A2: Vendor ID: V003 | Category: Engineering | Linked to Transactions
A3: Vendor ID | B3: V003 | D3: ← BACK TO LEDGER INDEX
A5: Opening Balance | B5: =XLOOKUP($B$3,'Vendor Master'!A6:A15,'Vendor Master'!G6:G15,0) | D5: Total Debit | E5: =SUMIFS(Transactions!F:F,Transactions!C:C,$B$3) | G5: Total Credit | H5: =SUMIFS(Transactions!G:G,Transactions!C:C,$B$3)
A6: Closing Balance | B6: =B5+E5-H5
A8: Date | B8: Voucher No. | C8: Description | D8: Debit | E8: Credit | F8: Running Balance | G8: Reference | H8: Month | I8: Vendor ID
A9: =IFERROR(INDEX(Transactions!$A$6:$A$5000,AGGREGATE(15,6,(ROW(Transactions!$C$6:$C$5000)-ROW(Transactions!$C$6)+1)/(Transactions!$C$6:$C$5000=$B$3),ROWS($A$9:A9))),"") | B9: =IF($A9="","",INDEX(Transactions!$B$6:$B$5000,AGGREGATE(15,6,(ROW(Transactions!$C$6:$C$5000)-ROW(Transactions!$C$6)+1)/(Transactions!$C$6:$C$5000=$B$3),ROWS($A$9:A9)))) | C9: =IF($A9="","",INDEX(Transactions!$E$6:$E$5000,AGGREGATE(15,6,(ROW(Transactions!$C$6:$C$5000)-ROW(Transactions!$C$6)+1)/(Transactions!$C$6:$C$5000=$B$3),ROWS($A$9:A9)))) | D9: =IF($A9="","",INDEX(Transactions!$F$6:$F$5000,AGGREGATE(15,6,(ROW(Transactions!$C$6:$C$5000)-ROW(Transactions!$C$6)+1)/(Transactions!$C$6:$C$5000=$B$3),ROWS($A$9:A9)))) | E9: =IF($A9="","",INDEX(Transactions!$G$6:$G$5000,AGGREGATE(15,6,(ROW(Transactions!$C$6:$C$5000)-ROW(Transactions!$C$6)+1)/(Transactions!$C$6:$C$5000=$B$3),ROWS($A$9:A9)))) | F9: =IF($A9="","",$B$5+SUM($D$9:D9)-SUM($E$9:E9)) | G9: =IF($A9="","",INDEX(Transactions!$H$6:$H$5000,AGGREGATE(15,6,(ROW(Transactions!$C$6:$C$5000)-ROW(Transactions!$C$6)+1)/(Transactions!$C$6:$C$5000=$B$3),ROWS($A$9:A9)))) | H9: =IF($A9="","",TEXT($A9,"mmm-yyyy")) | I9: =IF($A9="","",$B$3)
A10: =IFERROR(INDEX(Transactions!$A$6:$A$5000,AGGREGATE(15,6,(ROW(Transactions!$C$6:$C$5000)-ROW(Transactions!$C$6)+1)/(Transactions!$C$6:$C$5000=$B$3),ROWS($A$9:A10))),"") | B10: =IF($A10="","",INDEX(Transactions!$B$6:$B$5000,AGGREGATE(15,6,(ROW(Transactions!$C$6:$C$5000)-ROW(Transactions!$C$6)+1)/(Transactions!$C$6:$C$5000=$B$3),ROWS($A$9:A10)))) | C10: =IF($A10="","",INDEX(Transactions!$E$6:$E$5000,AGGREGATE(15,6,(ROW(Transactions!$C$6:$C$5000)-ROW(Transactions!$C$6)+1)/(Transactions!$C$6:$C$5000=$B$3),ROWS($A$9:A10)))) | D10: =IF($A10="","",INDEX(Transactions!$F$6:$F$5000,AGGREGATE(15,6,(ROW(Transactions!$C$6:$C$5000)-ROW(Transactions!$C$6)+1)/(Transactions!$C$6:$C$5000=$B$3),ROWS($A$9:A10)))) | E10: =IF($A10="","",INDEX(Transactions!$G$6:$G$5000,AGGREGATE(15,6,(ROW(Transactions!$C$6:$C$5000)-ROW(Transactions!$C$6)+1)/(Transactions!$C$6:$C$5000=$B$3),ROWS($A$9:A10)))) | F10: =IF($A10="","",$B$5+SUM($D$9:D10)-SUM($E$9:E10)) | G10: =IF($A10="","",INDEX(Transactions!$H$6:$H$5000,AGGREGATE(15,6,(ROW(Transactions!$C$6:$C$5000)-ROW(Transactions!$C$6)+1)/(Transactions!$C$6:$C$5000=$B$3),ROWS($A$9:A10)))) | H10: =IF($A10="","",TEXT($A10,"mmm-yyyy")) | I10: =IF($A10="","",$B$3)
A11: =IFERROR(INDEX(Transactions!$A$6:$A$5000,AGGREGATE(15,6,(ROW(Transactions!$C$6:$C$5000)-ROW(Transactions!$C$6)+1)/(Transactions!$C$6:$C$5000=$B$3),ROWS($A$9:A11))),"") | B11: =IF($A11="","",INDEX(Transactions!$B$6:$B$5000,AGGREGATE(15,6,(ROW(Transactions!$C$6:$C$5000)-ROW(Transactions!$C$6)+1)/(Transactions!$C$6:$C$5000=$B$3),ROWS($A$9:A11)))) | C11: =IF($A11="","",INDEX(Transactions!$E$6:$E$5000,AGGREGATE(15,6,(ROW(Transactions!$C$6:$C$5000)-ROW(Transactions!$C$6)+1)/(Transactions!$C$6:$C$5000=$B$3),ROWS($A$9:A11)))) | D11: =IF($A11="","",INDEX(Transactions!$F$6:$F$5000,AGGREGATE(15,6,(ROW(Transactions!$C$6:$C$5000)-ROW(Transactions!$C$6)+1)/(Transactions!$C$6:$C$5000=$B$3),ROWS($A$9:A11)))) | E11: =IF($A11="","",INDEX(Transactions!$G$6:$G$5000,AGGREGATE(15,6,(ROW(Transactions!$C$6:$C$5000)-ROW(Transactions!$C$6)+1)/(Transactions!$C$6:$C$5000=$B$3),ROWS($A$9:A11)))) | F11: =IF($A11="","",$B$5+SUM($D$9:D11)-SUM($E$9:E11)) | G11: =IF($A11="","",INDEX(Transactions!$H$6:$H$5000,AGGREGATE(15,6,(ROW(Transactions!$C$6:$C$5000)-ROW(Transactions!$C$6)+1)/(Transactions!$C$6:$C$5000=$B$3),ROWS($A$9:A11)))) | H11: =IF($A11="","",TEXT($A11,"mmm-yyyy")) | I11: =IF($A11="","",$B$3)
A12: =IFERROR(INDEX(Transactions!$A$6:$A$5000,AGGREGATE(15,6,(ROW(Transactions!$C$6:$C$5000)-ROW(Transactions!$C$6)+1)/(Transactions!$C$6:$C$5000=$B$3),ROWS($A$9:A12))),"") | B12: =IF($A12="","",INDEX(Transactions!$B$6:$B$5000,AGGREGATE(15,6,(ROW(Transactions!$C$6:$C$5000)-ROW(Transactions!$C$6)+1)/(Transactions!$C$6:$C$5000=$B$3),ROWS($A$9:A12)))) | C12: =IF($A12="","",INDEX(Transactions!$E$6:$E$5000,AGGREGATE(15,6,(ROW(Transactions!$C$6:$C$5000)-ROW(Transactions!$C$6)+1)/(Transactions!$C$6:$C$5000=$B$3),ROWS($A$9:A12)))) | D12: =IF($A12="","",INDEX(Transactions!$F$6:$F$5000,AGGREGATE(15,6,(ROW(Transactions!$C$6:$C$5000)-ROW(Transactions!$C$6)+1)/(Transactions!$C$6:$C$5000=$B$3),ROWS($A$9:A12)))) | E12: =IF($A12="","",INDEX(Transactions!$G$6:$G$5000,AGGREGATE(15,6,(ROW(Transactions!$C$6:$C$5000)-ROW(Transactions!$C$6)+1)/(Transactions!$C$6:$C$5000=$B$3),ROWS($A$9:A12)))) | F12: =IF($A12="","",$B$5+SUM($D$9:D12)-SUM($E$9:E12)) | G12: =IF($A12="","",INDEX(Transactions!$H$6:$H$5000,AGGREGATE(15,6,(ROW(Transactions!$C$6:$C$5000)-ROW(Transactions!$C$6)+1)/(Transactions!$C$6:$C$5000=$B$3),ROWS($A$9:A12)))) | H12: =IF($A12="","",TEXT($A12,"mmm-yyyy")) | I12: =IF($A12="","",$B$3)
A13: =IFERROR(INDEX(Transactions!$A$6:$A$5000,AGGREGATE(15,6,(ROW(Transactions!$C$6:$C$5000)-ROW(Transactions!$C$6)+1)/(Transactions!$C$6:$C$5000=$B$3),ROWS($A$9:A13))),"") | B13: =IF($A13="","",INDEX(Transactions!$B$6:$B$5000,AGGREGATE(15,6,(ROW(Transactions!$C$6:$C$5000)-ROW(Transactions!$C$6)+1)/(Transactions!$C$6:$C$5000=$B$3),ROWS($A$9:A13)))) | C13: =IF($A13="","",INDEX(Transactions!$E$6:$E$5000,AGGREGATE(15,6,(ROW(Transactions!$C$6:$C$5000)-ROW(Transactions!$C$6)+1)/(Transactions!$C$6:$C$5000=$B$3),ROWS($A$9:A13)))) | D13: =IF($A13="","",INDEX(Transactions!$F$6:$F$5000,AGGREGATE(15,6,(ROW(Transactions!$C$6:$C$5000)-ROW(Transactions!$C$6)+1)/(Transactions!$C$6:$C$5000=$B$3),ROWS($A$9:A13)))) | E13: =IF($A13="","",INDEX(Transactions!$G$6:$G$5000,AGGREGATE(15,6,(ROW(Transactions!$C$6:$C$5000)-ROW(Transactions!$C$6)+1)/(Transactions!$C$6:$C$5000=$B$3),ROWS($A$9:A13)))) | F13: =IF($A13="","",$B$5+SUM($D$9:D13)-SUM($E$9:E13)) | G13: =IF($A13="","",INDEX(Transactions!$H$6:$H$5000,AGGREGATE(15,6,(ROW(Transactions!$C$6:$C$5000)-ROW(Transactions!$C$6)+1)/(Transactions!$C$6:$C$5000=$B$3),ROWS($A$9:A13)))) | H13: =IF($A13="","",TEXT($A13,"mmm-yyyy")) | I13: =IF($A13="","",$B$3)
A14: =IFERROR(INDEX(Transactions!$A$6:$A$5000,AGGREGATE(15,6,(ROW(Transactions!$C$6:$C$5000)-ROW(Transactions!$C$6)+1)/(Transactions!$C$6:$C$5000=$B$3),ROWS($A$9:A14))),"") | B14: =IF($A14="","",INDEX(Transactions!$B$6:$B$5000,AGGREGATE(15,6,(ROW(Transactions!$C$6:$C$5000)-ROW(Transactions!$C$6)+1)/(Transactions!$C$6:$C$5000=$B$3),ROWS($A$9:A14)))) | C14: =IF($A14="","",INDEX(Transactions!$E$6:$E$5000,AGGREGATE(15,6,(ROW(Transactions!$C$6:$C$5000)-ROW(Transactions!$C$6)+1)/(Transactions!$C$6:$C$5000=$B$3),ROWS($A$9:A14)))) | D14: =IF($A14="","",INDEX(Transactions!$F$6:$F$5000,AGGREGATE(15,6,(ROW(Transactions!$C$6:$C$5000)-ROW(Transactions!$C$6)+1)/(Transactions!$C$6:$C$5000=$B$3),ROWS($A$9:A14)))) | E14: =IF($A14="","",INDEX(Transactions!$G$6:$G$5000,AGGREGATE(15,6,(ROW(Transactions!$C$6:$C$5000)-ROW(Transactions!$C$6)+1)/(Transactions!$C$6:$C$5000=$B$3),ROWS($A$9:A14)))) | F14: =IF($A14="","",$B$5+SUM($D$9:D14)-SUM($E$9:E14)) | G14: =IF($A14="","",INDEX(Transactions!$H$6:$H$5000,AGGREGATE(15,6,(ROW(Transactions!$C$6:$C$5000)-ROW(Transactions!$C$6)+1)/(Transactions!$C$6:$C$5000=$B$3),ROWS($A$9:A14)))) | H14: =IF($A14="","",TEXT($A14,"mmm-yyyy")) | I14: =IF($A14="","",$B$3)
A15: =IFERROR(INDEX(Transactions!$A$6:$A$5000,AGGREGATE(15,6,(ROW(Transactions!$C$6:$C$5000)-ROW(Transactions!$C$6)+1)/(Transactions!$C$6:$C$5000=$B$3),ROWS($A$9:A15))),"") | B15: =IF($A15="","",INDEX(Transactions!$B$6:$B$5000,AGGREGATE(15,6,(ROW(Transactions!$C$6:$C$5000)-ROW(Transactions!$C$6)+1)/(Transactions!$C$6:$C$5000=$B$3),ROWS($A$9:A15)))) | C15: =IF($A15="","",INDEX(Transactions!$E$6:$E$5000,AGGREGATE(15,6,(ROW(Transactions!$C$6:$C$5000)-ROW(Transactions!$C$6)+1)/(Transactions!$C$6:$C$5000=$B$3),ROWS($A$9:A15)))) | D15: =IF($A15="","",INDEX(Transactions!$F$6:$F$5000,AGGREGATE(15,6,(ROW(Transactions!$C$6:$C$5000)-ROW(Transactions!$C$6)+1)/(Transactions!$C$6:$C$5000=$B$3),ROWS($A$9:A15)))) | E15: =IF($A15="","",INDEX(Transactions!$G$6:$G$5000,AGGREGATE(15,6,(ROW(Transactions!$C$6:$C$5000)-ROW(Transactions!$C$6)+1)/(Transactions!$C$6:$C$5000=$B$3),ROWS($A$9:A15)))) | F15: =IF($A15="","",$B$5+SUM($D$9:D15)-SUM($E$9:E15)) | G15: =IF($A15="","",INDEX(Transactions!$H$6:$H$5000,AGGREGATE(15,6,(ROW(Transactions!$C$6:$C$5000)-ROW(Transactions!$C$6)+1)/(Transactions!$C$6:$C$5000=$B$3),ROWS($A$9:A15)))) | H15: =IF($A15="","",TEXT($A15,"mmm-yyyy")) | I15: =IF($A15="","",$B$3)
A16: =IFERROR(INDEX(Transactions!$A$6:$A$5000,AGGREGATE(15,6,(ROW(Transactions!$C$6:$C$5000)-ROW(Transactions!$C$6)+1)/(Transactions!$C$6:$C$5000=$B$3),ROWS($A$9:A16))),"") | B16: =IF($A16="","",INDEX(Transactions!$B$6:$B$5000,AGGREGATE(15,6,(ROW(Transactions!$C$6:$C$5000)-ROW(Transactions!$C$6)+1)/(Transactions!$C$6:$C$5000=$B$3),ROWS($A$9:A16)))) | C16: =IF($A16="","",INDEX(Transactions!$E$6:$E$5000,AGGREGATE(15,6,(ROW(Transactions!$C$6:$C$5000)-ROW(Transactions!$C$6)+1)/(Transactions!$C$6:$C$5000=$B$3),ROWS($A$9:A16)))) | D16: =IF($A16="","",INDEX(Transactions!$F$6:$F$5000,AGGREGATE(15,6,(ROW(Transactions!$C$6:$C$5000)-ROW(Transactions!$C$6)+1)/(Transactions!$C$6:$C$5000=$B$3),ROWS($A$9:A16)))) | E16: =IF($A16="","",INDEX(Transactions!$G$6:$G$5000,AGGREGATE(15,6,(ROW(Transactions!$C$6:$C$5000)-ROW(Transactions!$C$6)+1)/(Transactions!$C$6:$C$5000=$B$3),ROWS($A$9:A16)))) | F16: =IF($A16="","",$B$5+SUM($D$9:D16)-SUM($E$9:E16)) | G16: =IF($A16="","",INDEX(Transactions!$H$6:$H$5000,AGGREGATE(15,6,(ROW(Transactions!$C$6:$C$5000)-ROW(Transactions!$C$6)+1)/(Transactions!$C$6:$C$5000=$B$3),ROWS($A$9:A16)))) | H16: =IF($A16="","",TEXT($A16,"mmm-yyyy")) | I16: =IF($A16="","",$B$3)
A17: =IFERROR(INDEX(Transactions!$A$6:$A$5000,AGGREGATE(15,6,(ROW(Transactions!$C$6:$C$5000)-ROW(Transactions!$C$6)+1)/(Transactions!$C$6:$C$5000=$B$3),ROWS($A$9:A17))),"") | B17: =IF($A17="","",INDEX(Transactions!$B$6:$B$5000,AGGREGATE(15,6,(ROW(Transactions!$C$6:$C$5000)-ROW(Transactions!$C$6)+1)/(Transactions!$C$6:$C$5000=$B$3),ROWS($A$9:A17)))) | C17: =IF($A17="","",INDEX(Transactions!$E$6:$E$5000,AGGREGATE(15,6,(ROW(Transactions!$C$6:$C$5000)-ROW(Transactions!$C$6)+1)/(Transactions!$C$6:$C$5000=$B$3),ROWS($A$9:A17)))) | D17: =IF($A17="","",INDEX(Transactions!$F$6:$F$5000,AGGREGATE(15,6,(ROW(Transactions!$C$6:$C$5000)-ROW(Transactions!$C$6)+1)/(Transactions!$C$6:$C$5000=$B$3),ROWS($A$9:A17)))) | E17: =IF($A17="","",INDEX(Transactions!$G$6:$G$5000,AGGREGATE(15,6,(ROW(Transactions!$C$6:$C$5000)-ROW(Transactions!$C$6)+1)/(Transactions!$C$6:$C$5000=$B$3),ROWS($A$9:A17)))) | F17: =IF($A17="","",$B$5+SUM($D$9:D17)-SUM($E$9:E17)) | G17: =IF($A17="","",INDEX(Transactions!$H$6:$H$5000,AGGREGATE(15,6,(ROW(Transactions!$C$6:$C$5000)-ROW(Transactions!$C$6)+1)/(Transactions!$C$6:$C$5000=$B$3),ROWS($A$9:A17)))) | H17: =IF($A17="","",TEXT($A17,"mmm-yyyy")) | I17: =IF($A17="","",$B$3)
A18: =IFERROR(INDEX(Transactions!$A$6:$A$5000,AGGREGATE(15,6,(ROW(Transactions!$C$6:$C$5000)-ROW(Transactions!$C$6)+1)/(Transactions!$C$6:$C$5000=$B$3),ROWS($A$9:A18))),"") | B18: =IF($A18="","",INDEX(Transactions!$B$6:$B$5000,AGGREGATE(15,6,(ROW(Transactions!$C$6:$C$5000)-ROW(Transactions!$C$6)+1)/(Transactions!$C$6:$C$5000=$B$3),ROWS($A$9:A18)))) | C18: =IF($A18="","",INDEX(Transactions!$E$6:$E$5000,AGGREGATE(15,6,(ROW(Transactions!$C$6:$C$5000)-ROW(Transactions!$C$6)+1)/(Transactions!$C$6:$C$5000=$B$3),ROWS($A$9:A18)))) | D18: =IF($A18="","",INDEX(Transactions!$F$6:$F$5000,AGGREGATE(15,6,(ROW(Transactions!$C$6:$C$5000)-ROW(Transactions!$C$6)+1)/(Transactions!$C$6:$C$5000=$B$3),ROWS($A$9:A18)))) | E18: =IF($A18="","",INDEX(Transactions!$G$6:$G$5000,AGGREGATE(15,6,(ROW(Transactions!$C$6:$C$5000)-ROW(Transactions!$C$6)+1)/(Transactions!$C$6:$C$5000=$B$3),ROWS($A$9:A18)))) | F18: =IF($A18="","",$B$5+SUM($D$9:D18)-SUM($E$9:E18)) | G18: =IF($A18="","",INDEX(Transactions!$H$6:$H$5000,AGGREGATE(15,6,(ROW(Transactions!$C$6:$C$5000)-ROW(Transactions!$C$6)+1)/(Transactions!$C$6:$C$5000=$B$3),ROWS($A$9:A18)))) | H18: =IF($A18="","",TEXT($A18,"mmm-yyyy")) | I18: =IF($A18="","",$B$3)
A19: =IFERROR(INDEX(Transactions!$A$6:$A$5000,AGGREGATE(15,6,(ROW(Transactions!$C$6:$C$5000)-ROW(Transactions!$C$6)+1)/(Transactions!$C$6:$C$5000=$B$3),ROWS($A$9:A19))),"") | B19: =IF($A19="","",INDEX(Transactions!$B$6:$B$5000,AGGREGATE(15,6,(ROW(Transactions!$C$6:$C$5000)-ROW(Transactions!$C$6)+1)/(Transactions!$C$6:$C$5000=$B$3),ROWS($A$9:A19)))) | C19: =IF($A19="","",INDEX(Transactions!$E$6:$E$5000,AGGREGATE(15,6,(ROW(Transactions!$C$6:$C$5000)-ROW(Transactions!$C$6)+1)/(Transactions!$C$6:$C$5000=$B$3),ROWS($A$9:A19)))) | D19: =IF($A19="","",INDEX(Transactions!$F$6:$F$5000,AGGREGATE(15,6,(ROW(Transactions!$C$6:$C$5000)-ROW(Transactions!$C$6)+1)/(Transactions!$C$6:$C$5000=$B$3),ROWS($A$9:A19)))) | E19: =IF($A19="","",INDEX(Transactions!$G$6:$G$5000,AGGREGATE(15,6,(ROW(Transactions!$C$6:$C$5000)-ROW(Transactions!$C$6)+1)/(Transactions!$C$6:$C$5000=$B$3),ROWS($A$9:A19)))) | F19: =IF($A19="","",$B$5+SUM($D$9:D19)-SUM($E$9:E19)) | G19: =IF($A19="","",INDEX(Transactions!$H$6:$H$5000,AGGREGATE(15,6,(ROW(Transactions!$C$6:$C$5000)-ROW(Transactions!$C$6)+1)/(Transactions!$C$6:$C$5000=$B$3),ROWS($A$9:A19)))) | H19: =IF($A19="","",TEXT($A19,"mmm-yyyy")) | I19: =IF($A19="","",$B$3)
A20: =IFERROR(INDEX(Transactions!$A$6:$A$5000,AGGREGATE(15,6,(ROW(Transactions!$C$6:$C$5000)-ROW(Transactions!$C$6)+1)/(Transactions!$C$6:$C$5000=$B$3),ROWS($A$9:A20))),"") | B20: =IF($A20="","",INDEX(Transactions!$B$6:$B$5000,AGGREGATE(15,6,(ROW(Transactions!$C$6:$C$5000)-ROW(Transactions!$C$6)+1)/(Transactions!$C$6:$C$5000=$B$3),ROWS($A$9:A20)))) | C20: =IF($A20="","",INDEX(Transactions!$E$6:$E$5000,AGGREGATE(15,6,(ROW(Transactions!$C$6:$C$5000)-ROW(Transactions!$C$6)+1)/(Transactions!$C$6:$C$5000=$B$3),ROWS($A$9:A20)))) | D20: =IF($A20="","",INDEX(Transactions!$F$6:$F$5000,AGGREGATE(15,6,(ROW(Transactions!$C$6:$C$5000)-ROW(Transactions!$C$6)+1)/(Transactions!$C$6:$C$5000=$B$3),ROWS($A$9:A20)))) | E20: =IF($A20="","",INDEX(Transactions!$G$6:$G$5000,AGGREGATE(15,6,(ROW(Transactions!$C$6:$C$5000)-ROW(Transactions!$C$6)+1)/(Transactions!$C$6:$C$5000=$B$3),ROWS($A$9:A20)))) | F20: =IF($A20="","",$B$5+SUM($D$9:D20)-SUM($E$9:E20)) | G20: =IF($A20="","",INDEX(Transactions!$H$6:$H$5000,AGGREGATE(15,6,(ROW(Transactions!$C$6:$C$5000)-ROW(Transactions!$C$6)+1)/(Transactions!$C$6:$C$5000=$B$3),ROWS($A$9:A20)))) | H20: =IF($A20="","",TEXT($A20,"mmm-yyyy")) | I20: =IF($A20="","",$B$3)
